Workbook

Sheet DETALLE FACT PEAJES
A1: SIC | B1: NIC | C1: DES_CLIENTE | D1: NIVEL TENSION | E1: CONSUMO | F1: Aproximacion a decenas Energia | G1: PEAJES REGIONALES NO REGULADOS OTRO | H1: PEAJES REGIONALES REGULADOS OTROS | I1: TARIFA ACTIVA | J1: PEN. ENERGIA REACTIVA PEAJES | K1: ENERGIA REACTIVA PEAJES | L1: PEN. REACTIVA IND ($) - M A CARGAR | M1: PEN. REACTIVA IND ($) - M APLICADA FINAL | N1: TARIFA REACTIVA | O1: M | P1: AGPE | Q1: PROPIEDAD
A2: Frt07175 | B2: 1415542 | C2: 423 INVERSIONES EN RECREACION, DEPORTE Y SALUD S.A. - PLAZUELA | D2: 1 | E2: 29416.905 | F2: -3.05 | H2: 3176900.7 | I2: =(G2+H2)/E2 -> 107.99575 | J2: 7792.33 | K2: 47.76 | L2: =(J2*O2)-J2 -> 0 | M2: =(J2*O2) -> 7792.33 | N2: =M2/K2/O2 -> 163.15599 | O2: 1 | Q2: =_xlfn.XLOOKUP(A2,'CONSOLIDADO PEAJES'!H:H,'CONSOLIDADO PEAJES'!AC:AC) -> 1
A3: Frt18685 | B3: 1307882 | C3: 038 INDUSTRIA COLOMBIANA DE CONFECCIONES S.A. INCOCO S.A. ALM NO 27 | D3: 1 | E3: 2950.422 | F3: 4.88 | H3: 420232.91 | I3: =(G3+H3)/E3 -> 142.43146 | J3: 672.21 | K3: 3.402 | L3: =(J3*O3)-J3 -> 0 | M3: =(J3*O3) -> 672.21 | N3: =M3/K3/O3 -> 197.59259 | O3: 1 | Q3: =_xlfn.XLOOKUP(A3,'CONSOLIDADO PEAJES'!H:H,'CONSOLIDADO PEAJES'!AC:AC) -> 0
A4: Frt18958 | B4: 1288986 | C4: 08 INDUSTRIA COLOMBIANA DE CONFECCIONES S.A. INCOCO S.A. ALM NO 25 | D4: 1 | E4: 4836.756 | F4: 0.91 | H4: 522349.09 | I4: =(G4+H4)/E4 -> 107.99575 | L4: =(J4*O4)-J4 -> 0 | M4: =(J4*O4) -> 0 | N4: 163.15599 | O4: 1 | Q4: =_xlfn.XLOOKUP(A4,'CONSOLIDADO PEAJES'!H:H,'CONSOLIDADO PEAJES'!AC:AC) -> 1
A5: Frt25486 | B5: 1288751 | C5: 09 INDUSTRIA COLOMBIANA DE CONFECCIONES SA | D5: 1 | E5: 3269.341 | F5: 0.12 | H5: 353074.93 | I5: =(G5+H5)/E5 -> 107.99575 | J5: 164.95 | K5: 1.011 | L5: =(J5*O5)-J5 -> 0 | M5: =(J5*O5) -> 164.95 | N5: 163.15599 | O5: 1 | Q5: =_xlfn.XLOOKUP(A5,'CONSOLIDADO PEAJES'!H:H,'CONSOLIDADO PEAJES'!AC:AC) -> 1
A6: Frt26227 | B6: 1307886 | C6: 039 INDUSTRIA COLOMBIANA DE CONFECCIONES SA | D6: 1 | E6: 2677.293 | F6: -3.64 | H6: 264059.13 | I6: =(G6+H6)/E6 -> 98.629149 | J6: 14054.51 | K6: 91.388 | L6: =(J6*O6)-J6 -> 42163.53 | M6: =(J6*O6) -> 56218.04 | N6: =M6/K6/O6 -> 153.78945 | O6: 4 | Q6: 1
A7: Frt26506 | B7: 1412055 | C7: 341 INVERSIONES EN RECREACION, DEPORTE Y SALUD S.A. - EJECUTIVOS | D7: 1 | E7: 20551.08 | F7: -1.07 | H7: 2219429.3 | I7: =(G7+H7)/E7 -> 107.99575 | J7: 56601.77 | K7: 346.918 | L7: =(J7*O7)-J7 -> 0 | M7: =(J7*O7) -> 56601.77 | N7: 163.15599 | O7: 1 | Q7: =_xlfn.XLOOKUP(A7,'CONSOLIDADO PEAJES'!H:H,'CONSOLIDADO PEAJES'!AC:AC) -> 1
A8: Frt26688 | B8: 1412141 | C8: 368 INVERSIONES EN RECREACIION DEPORTE Y SALUD S.A. - BODYTECH CARIBE PLAZA | D8: 1 | E8: 31177.301 | F8: 4.73 | H8: 4440628.5 | I8: =(G8+H8)/E8 -> 142.43146 | J8: 51626.77 | K8: 261.28 | L8: =(J8*O8)-J8 -> 0 | M8: =(J8*O8) -> 51626.77 | N8: =M8/K8/O8 -> 197.59174 | O8: 1 | Q8: =_xlfn.XLOOKUP(A8,'CONSOLIDADO PEAJES'!H:H,'CONSOLIDADO PEAJES'!AC:AC) -> 0
A9: Frt31432 | B9: 1386094 | C9: 236 PROMOTORA BELLATRIX SAS | D9: 1 | E9: 6158.302 | F9: -4.32 | H9: 877135.94 | I9: =(G9+H9)/E9 -> 142.43146 | J9: 5088.38 | K9: 25.752 | L9: =(J9*O9)-J9 -> 0 | M9: =(J9*O9) -> 5088.38 | N9: =M9/K9/O9 -> 197.59164 | O9: 1 | Q9: =_xlfn.XLOOKUP(A9,'CONSOLIDADO PEAJES'!H:H,'CONSOLIDADO PEAJES'!AC:AC) -> 0
A10: Frt35190 | B10: 1340629 | C10: 060 BESPOKE COLOMBIA S.A.S. | D10: 1 | E10: 6890.45 | F10: 3.15 | H10: 981416.85 | I10: =(G10+H10)/E10 -> 142.43146 | L10: =(J10*O10)-J10 -> 0 | M10: =(J10*O10) -> 0 | N10: 197.59164 | O10: 1 | Q10: =_xlfn.XLOOKUP(A10,'CONSOLIDADO PEAJES'!H:H,'CONSOLIDADO PEAJES'!AC:AC) -> 0
A11: Frt36869 | B11: 1415365 | C11: 389 NCS S. A. S. CL 44 8 43 LOC A189 | D11: 1 | E11: 4048.934 | F11: 4.47 | H11: 437267.66 | I11: =(G11+H11)/E11 -> 107.99575 | J11: 29757.87 | K11: 182.389 | L11: =(J11*O11)-J11 -> 0 | M11: =(J11*O11) -> 29757.87 | N11: 163.15599 | O11: 1 | Q11: =_xlfn.XLOOKUP(A11,'CONSOLIDADO PEAJES'!H:H,'CONSOLIDADO PEAJES'!AC:AC) -> 1
A12: Frt36870 | B12: 1380304 | C12: 215 NCS MODA SAS | D12: 1 | E12: 5676.727 | F12: -2.39 | H12: 613062.39 | I12: =(G12+H12)/E12 -> 107.99575 | L12: =(J12*O12)-J12 -> 0 | M12: =(J12*O12) -> 0 | N12: 163.15599 | O12: 1 | Q12: =_xlfn.XLOOKUP(A12,'CONSOLIDADO PEAJES'!H:H,'CONSOLIDADO PEAJES'!AC:AC) -> 1
A13: Frt36871 | B13: 1356065 | C13: 124 NCS MODA SAS | D13: 1 | E13: 5150.798 | F13: 4.32 | H13: 733635.68 | I13: =(G13+H13)/E13 -> 142.43146 | L13: =(J13*O13)-J13 -> 0 | M13: =(J13*O13) -> 0 | N13: 197.59164 | O13: 1 | Q13: =_xlfn.XLOOKUP(A13,'CONSOLIDADO PEAJES'!H:H,'CONSOLIDADO PEAJES'!AC:AC) -> 0
A14: Frt37173 | B14: 1317345 | C14: 043 GASTRONOMIA ITALIANA EN COLOMBIA SAS | D14: 1 | E14: 17674.865 | F14: -0.57 | H14: 1908810.3 | I14: =(G14+H14)/E14 -> 107.99575 | J14: 150.27 | K14: 0.921 | L14: =(J14*O14)-J14 -> 0 | M14: =(J14*O14) -> 150.27 | N14: 163.15599 | O14: 1 | Q14: =_xlfn.XLOOKUP(A14,'CONSOLIDADO PEAJES'!H:H,'CONSOLIDADO PEAJES'!AC:AC) -> 1
A15: Frt40322 | B15: 1303762 | C15: 022 BANCO DAVIVIENDA SA | D15: 1 | E15: 3951.921 | F15: -4.09 | H15: 426790.67 | I15: =(G15+H15)/E15 -> 107.99575 | J15: 17083.42 | K15: 104.706 | L15: =(J15*O15)-J15 -> 0 | M15: =(J15*O15) -> 17083.42 | N15: 163.15599 | O15: 1 | Q15: =_xlfn.XLOOKUP(A15,'CONSOLIDADO PEAJES'!H:H,'CONSOLIDADO PEAJES'!AC:AC) -> 1
A16: Frt41384 | B16: 1303703 | C16: 024 BANCO DAVIVIENDA SA | D16: 1 | E16: 3613.953 | F16: 3.66 | H16: 390291.56 | I16: =(G16+H16)/E16 -> 107.99575 | J16: 8654.78 | K16: 53.046 | L16: =(J16*O16)-J16 -> 0 | M16: =(J16*O16) -> 8654.78 | N16: 163.15599 | O16: 1 | Q16: =_xlfn.XLOOKUP(A16,'CONSOLIDADO PEAJES'!H:H,'CONSOLIDADO PEAJES'!AC:AC) -> 1
A17: Frt41385 | B17: 1304933 | C17: 036 BANCO DAVIVIENDA SA | D17: 1 | E17: 7896.459 | F17: -3.53 | H17: 852784.01 | I17: =(G17+H17)/E17 -> 107.99575 | J17: 32159.52 | K17: 197.109 | L17: =(J17*O17)-J17 -> 0 | M17: =(J17*O17) -> 32159.52 | N17: 163.15599 | O17: 1 | Q17: =_xlfn.XLOOKUP(A17,'CONSOLIDADO PEAJES'!H:H,'CONSOLIDADO PEAJES'!AC:AC) -> 1
A18: Frt41386 | B18: 1303705 | C18: 025 BANCO DAVIVIENDA SA | D18: 1 | E18: 6134.369 | F18: 4.22 | H18: 662485.78 | I18: =(G18+H18)/E18 -> 107.99575 | L18: =(J18*O18)-J18 -> 0 | M18: =(J18*O18) -> 0 | N18: 163.15599 | O18: 1 | Q18: =_xlfn.XLOOKUP(A18,'CONSOLIDADO PEAJES'!H:H,'CONSOLIDADO PEAJES'!AC:AC) -> 1
A19: Frt41388 | B19: 1303708 | C19: 026 BANCO DAVIVIENDA SA | D19: 1 | E19: 4831.433 | F19: -4.23 | H19: 521774.23 | I19: =(G19+H19)/E19 -> 107.99575 | L19: =(J19*O19)-J19 -> 0 | M19: =(J19*O19) -> 0 | N19: 163.15599 | O19: 1 | Q19: =_xlfn.XLOOKUP(A19,'CONSOLIDADO PEAJES'!H:H,'CONSOLIDADO PEAJES'!AC:AC) -> 1
A20: Frt41402 | B20: 1303711 | C20: 027 BANCO DAVIVIENDA SA | D20: 1 | E20: 5767.456 | F20: 0.99 | H20: 622860.74 | I20: =(G20+H20)/E20 -> 107.99575 | J20: 4418.27 | K20: 27.08 | L20: =(J20*O20)-J20 -> 0 | M20: =(J20*O20) -> 4418.27 | N20: 163.15599 | O20: 1 | Q20: =_xlfn.XLOOKUP(A20,'CONSOLIDADO PEAJES'!H:H,'CONSOLIDADO PEAJES'!AC:AC) -> 1
A21: Frt42285 | B21: 1303716 | C21: 028 BANCO DAVIVIENDA SA | D21: 1 | E21: 4595.121 | F21: 3.94 | H21: 496253.54 | I21: =(G21+H21)/E21 -> 107.99575 | J21: 192.52 | K21: 1.18 | L21: =(J21*O21)-J21 -> 0 | M21: =(J21*O21) -> 192.52 | N21: 163.15599 | O21: 1 | Q21: =_xlfn.XLOOKUP(A21,'CONSOLIDADO PEAJES'!H:H,'CONSOLIDADO PEAJES'!AC:AC) -> 1
A22: Frt42286 | B22: 1303717 | C22: 029 BANCO DAVIVIENDA SA | D22: 1 | E22: 5602.074 | F22: -0.18 | H22: 605000.18 | I22: =(G22+H22)/E22 -> 107.99575 | L22: =(J22*O22)-J22 -> 0 | M22: =(J22*O22) -> 0 | N22: 163.15599 | O22: 1 | Q22: =_xlfn.XLOOKUP(A22,'CONSOLIDADO PEAJES'!H:H,'CONSOLIDADO PEAJES'!AC:AC) -> 1
A23: Frt42287 | B23: 1303720 | C23: 030 BANCO DAVIVIENDA SA | D23: 1 | E23: 4715.809 | F23: 0.44 | H23: 671679.56 | I23: =(G23+H23)/E23 -> 142.43146 | L23: =(J23*O23)-J23 -> 0 | M23: =(J23*O23) -> 0 | N23: 197.59164 | O23: 1 | Q23: =_xlfn.XLOOKUP(A23,'CONSOLIDADO PEAJES'!H:H,'CONSOLIDADO PEAJES'!AC:AC) -> 0
A24: Frt43155 | B24: 1303764 | C24: 031 BANCO DAVIVIENDA SA | D24: 1 | E24: 3803.929 | F24: -0.88 | H24: 410808.17 | I24: =(G24+H24)/E24 -> 107.99575 | J24: 7162.71 | K24: 43.901 | L24: =(J24*O24)-J24 -> 0 | M24: =(J24*O24) -> 7162.71 | N24: 163.15599 | O24: 1 | Q24: =_xlfn.XLOOKUP(A24,'CONSOLIDADO PEAJES'!H:H,'CONSOLIDADO PEAJES'!AC:AC) -> 1
A25: Frt43156 | B25: 1303907 | C25: 032 BANCO DAVIVIENDA SA | D25: 1 | E25: 3061.141 | F25: 0.95 | H25: 330590.22 | I25: =(G25+H25)/E25 -> 107.99575 | J25: 13748.83 | K25: 84.268 | L25: =(J25*O25)-J25 -> 0 | M25: =(J25*O25) -> 13748.83 | N25: 163.15599 | O25: 1 | Q25: =_xlfn.XLOOKUP(A25,'CONSOLIDADO PEAJES'!H:H,'CONSOLIDADO PEAJES'!AC:AC) -> 1
A26: Frt43157 | B26: 1303767 | C26: 033 BANCO DAVIVIENDA SA | D26: 1 | E26: 10148.798 | F26: 2 | H26: 1096027.1 | I26: =(G26+H26)/E26 -> 107.99575 | J26: 60140.95 | K26: 368.61 | L26: =(J26*O26)-J26 -> 0 | M26: =(J26*O26) -> 60140.95 | N26: 163.15599 | O26: 1 | Q26: =_xlfn.XLOOKUP(A26,'CONSOLIDADO PEAJES'!H:H,'CONSOLIDADO PEAJES'!AC:AC) -> 1
A27: Frt43194 | B27: 1303924 | C27: 034 BANCO DAVIVIENDA SA | D27: 1 | E27: 5145.421 | F27: -1.14 | H27: 555683.6 | I27: =(G27+H27)/E27 -> 107.99575 | J27: 3367.54 | K27: 20.64 | L27: =(J27*O27)-J27 -> 0 | M27: =(J27*O27) -> 3367.54 | N27: 163.15599 | O27: 1 | Q27: =_xlfn.XLOOKUP(A27,'CONSOLIDADO PEAJES'!H:H,'CONSOLIDADO PEAJES'!AC:AC) -> 1
A28: Frt45072 | B28: 1340624 | C28: 058 HL OPERADORES S.A.S (SEDE 5) | D28: 1 | E28: 8427.25 | F28: 2.42 | H28: 910107.18 | I28: =(G28+H28)/E28 -> 107.99575 | J28: 26890.4 | K28: 164.814 | L28: =(J28*O28)-J28 -> 0 | M28: =(J28*O28) -> 26890.4 | N28: 163.15599 | O28: 1 | Q28: =_xlfn.XLOOKUP(A28,'CONSOLIDADO PEAJES'!H:H,'CONSOLIDADO PEAJES'!AC:AC) -> 1
A29: Frt45621 | B29: 1406183 | C29: 317 PAISAR SAS - SAN LAZARO ART HOTEL | D29: 1 | E29: 44112.82 | F29: 2.92 | H29: 4763997.1 | I29: =(G29+H29)/E29 -> 107.99575 | L29: =(J29*O29)-J29 -> 0 | M29: =(J29*O29) -> 0 | N29: 163.15599 | O29: 1 | Q29: =_xlfn.XLOOKUP(A29,'CONSOLIDADO PEAJES'!H:H,'CONSOLIDADO PEAJES'!AC:AC) -> 1
A30: Frt45865 | B30: 1340528 | C30: 055 SATI BRO S.A.S | D30: 1 | E30: 15864.841 | F30: -2.47 | H30: 2259652.5 | I30: =(G30+H30)/E30 -> 142.43146 | L30: =(J30*O30)-J30 -> 0 | M30: =(J30*O30) -> 0 | N30: 197.59164 | O30: 1 | Q30: =_xlfn.XLOOKUP(A30,'CONSOLIDADO PEAJES'!H:H,'CONSOLIDADO PEAJES'!AC:AC) -> 0
A31: Frt49106 | B31: 1415362 | C31: 424 PROYECTOS E INVERSIONES M Y C SAS - BENEDETTO RISTORANTE | D31: 1 | E31: 8878.21 | F31: -0.96 | H31: 958808.95 | I31: =(G31+H31)/E31 -> 107.99575 | J31: 22602.01 | K31: 138.53 | L31: =(J31*O31)-J31 -> 0 | M31: =(J31*O31) -> 22602.01 | N31: 163.15599 | O31: 1 | Q31: =_xlfn.XLOOKUP(A31,'CONSOLIDADO PEAJES'!H:H,'CONSOLIDADO PEAJES'!AC:AC) -> 1
A32: Frt50758 | B32: 1281726 | C32: 02 GALAVANTA TRAVEL SAS | D32: 1 | E32: 144.515 | F32: -3.48 | H32: 20583.48 | I32: =(G32+H32)/E32 -> 142.43144 | L32: =(J32*O32)-J32 -> 0 | M32: =(J32*O32) -> 0 | N32: 197.59164 | O32: 1 | Q32: =_xlfn.XLOOKUP(A32,'CONSOLIDADO PEAJES'!H:H,'CONSOLIDADO PEAJES'!AC:AC) -> 0
A33: Frt50896 | B33: 1282988 | C33: 04 FUNDACION RONALD MC DONALD SEDE CARTAGENA | D33: 1 | E33: 1721.572 | F33: 1.34 | H33: 185922.46 | I33: =(G33+H33)/E33 -> 107.99575 | J33: 20176.2 | K33: 123.662 | L33: =(J33*O33)-J33 -> 100881 | M33: =(J33*O33) -> 121057.2 | N33: 163.15599 | O33: 6 | Q33: =_xlfn.XLOOKUP(A33,'CONSOLIDADO PEAJES'!H:H,'CONSOLIDADO PEAJES'!AC:AC) -> 1
A34: Frt50897 | B34: 1282989 | C34: 05 SEVEN COMPANY SAS | D34: 1 | E34: 171.969 | F34: -1.92 | H34: 18571.92 | I34: =(G34+H34)/E34 -> 107.99574 | L34: =(J34*O34)-J34 -> 0 | M34: =(J34*O34) -> 0 | N34: 163.15599 | O34: 1 | Q34: =_xlfn.XLOOKUP(A34,'CONSOLIDADO PEAJES'!H:H,'CONSOLIDADO PEAJES'!AC:AC) -> 1
A35: Frt50921 | B35: 1282806 | C35: 06 ACONDESA MERCAPOLLO LC1 MTR | D35: 1 | E35: 591.758 | F35: 2.43 | H35: 84284.96 | I35: =(G35+H35)/E35 -> 142.43147 | J35: 39972.61 | K35: 202.299 | L35: =(J35*O35)-J35 -> 199863.05 | M35: =(J35*O35) -> 239835.66 | N35: 197.59164 | O35: 6 | Q35: =_xlfn.XLOOKUP(A35,'CONSOLIDADO PEAJES'!H:H,'CONSOLIDADO PEAJES'!AC:AC) -> 0
A36: Frt50975 | B36: 1282807 | C36: 07 ACONDESA MERCAPOLLO LC2 MTR | D36: 1 | E36: 5678.609 | F36: 3.21 | H36: 808812.57 | I36: =(G36+H36)/E36 -> 142.43146 | J36: 1344.22 | K36: 6.803 | L36: =(J36*O36)-J36 -> 0 | M36: =(J36*O36) -> 1344.22 | N36: 197.59164 | O36: 1 | Q36: =_xlfn.XLOOKUP(A36,'CONSOLIDADO PEAJES'!H:H,'CONSOLIDADO PEAJES'!AC:AC) -> 0
A37: Frt51639 | B37: 1295066 | C37: 021 HOTEL ITACO | D37: 1 | E37: 1724.057 | F37: 0.04 | H37: 245559.96 | I37: =(G37+H37)/E37 -> 142.43146 | L37: =(J37*O37)-J37 -> 0 | M37: =(J37*O37) -> 0 | N37: 197.59164 | O37: 1 | Q37: =_xlfn.XLOOKUP(A37,'CONSOLIDADO PEAJES'!H:H,'CONSOLIDADO PEAJES'!AC:AC) -> 0
A38: Frt51650 | B38: 1295340 | C38: 010 LITOGRAF�A JULIO GAMEZ VALLEDUPAR | D38: 1 | E38: 3513.475 | F38: -1 | H38: 500429.37 | I38: =(G38+H38)/E38 -> 142.43146 | J38: 0 | K38: 11.699 | L38: =(J38*O38)-J38 -> 0 | M38: =(J38*O38) -> 0 | N38: 197.59164 | O38: 1 | P38: AGPE | Q38: =_xlfn.XLOOKUP(A38,'CONSOLIDADO PEAJES'!H:H,'CONSOLIDADO PEAJES'!AC:AC) -> 0
A39: Frt51790 | B39: 1296891 | C39: 011 WYNWOOD 1402 CTG | D39: 1 | E39: 543.485 | F39: -4.56 | H39: 58694.07 | I39: =(G39+H39)/E39 -> 107.99575 | J39: 0.49 | K39: 0.003 | L39: =(J39*O39)-J39 -> 0 | M39: =(J39*O39) -> 0.49 | N39: 163.15599 | O39: 1 | Q39: =_xlfn.XLOOKUP(A39,'CONSOLIDADO PEAJES'!H:H,'CONSOLIDADO PEAJES'!AC:AC) -> 1
A40: Frt51791 | B40: 1296893 | C40: 012 WYNWOOD 1302 CTG | D40: 1 | E40: 103.286 | F40: -4.45 | H40: 11154.45 | I40: =(G40+H40)/E40 -> 107.99576 | L40: =(J40*O40)-J40 -> 0 | M40: =(J40*O40) -> 0 | N40: 163.15599 | O40: 1 | Q40: =_xlfn.XLOOKUP(A40,'CONSOLIDADO PEAJES'!H:H,'CONSOLIDADO PEAJES'!AC:AC) -> 1
...

Sheet CONSOLIDADO PEAJES
A1: TIPO MERCADO | B1: NIC | C1: LIQ_NUM_FACTURA | D1: LIQ_NUM_FACTURA_OTROS | E1: LIQUIDACION | F1: NIT | G1: CODIGO | H1: SIC | I1: SUMI_COD_FENIX | J1: DES_CLIENTE | K1: CLAS_DESCRIP | L1: DES_CONCEPTOS | M1: PUNTA | N1: TIPO_SERVICIO | O1: VALOR | P1: CONSUMO | Q1: LIQ_FECHA | R1: LIQ_FECHA_INICIO | S1: LIQ_FECHA_FIN | T1: LIQ_FECHA_VENCIMIENTO | U1: LIQ_FECHA_VEN_OTROS | V1: NIVEL TENSION | W1: COMERCIALIZADOR | X1: CONT_NUMERO | Y1: CIUDAD | Z1: EJECUTIVO | AA1: COD_SUI | AB1: COD_NIU | AC1: PROPIEDAD_ACTIVOS | AD1: AGPE
A2: NO REGULADO | B2: 1333414 | D2: NH | E2: 941507 | F2: 9015884123 | G2: 48 | H2: Frt28526 | I2: 0 | J2: 048 EURO SUPERMERCADO - INVERSIONES EURO SA - MONTERIA | K2: PEAJE NO REGULADO | L2: CONSUMO BASE | M2: NORMAL | N2: SV120 | O2: 0 | P2: 59416.188 | Q2: 46031 | R2: 45992 | S2: 46022 | V2: 2 | W2: BIA ENERGY S.A.S. E.S.P | X2: BIA 48 | Y2: MONTERIA | Z2: INJERMAN GARCIA | AA2: 62371 | AB2: 21107168 | AC2: 1
A3: NO REGULADO | B3: 1405491 | D3: NH | E3: 941518 | F3: 9015884123 | G3: 305 | H3: Frt45137 | I3: 0 | J3: 305 PAISAR SAS | K3: PEAJE NO REGULADO | L3: Aproximacion a decenas Energia | M3: NORMAL | N3: SV120 | O3: 0.58 | P3: 0 | Q3: 46031 | R3: 45992 | S3: 46022 | V3: 2 | W3: BIA ENERGY S.A.S. E.S.P | X3: BIA 305 | Y3: CARTAGENA | Z3: INJERMAN GARCIA | AA3: 62371 | AB3: 19397544 | AC3: 1
A4: NO REGULADO | B4: 1333414 | D4: NH | E4: 941507 | F4: 9015884123 | G4: 48 | H4: Frt28526 | I4: 0 | J4: 048 EURO SUPERMERCADO - INVERSIONES EURO SA - MONTERIA | K4: PEAJE NO REGULADO | L4: PEN. ENERGIA REACTIVA PEAJES | M4: MEDIA | N4: SV120 | O4: 40237.69 | P4: 316.14 | Q4: 46031 | R4: 45992 | S4: 46022 | V4: 2 | W4: BIA ENERGY S.A.S. E.S.P | X4: BIA 48 | Y4: MONTERIA | Z4: INJERMAN GARCIA | AA4: 62371 | AB4: 21107168 | AC4: 1
A5: NO REGULADO | B5: 1333428 | D5: NH | E5: 941510 | F5: 9015884123 | G5: 49 | H5: Frt29125 | I5: 0 | J5: 049 INVERSIONES EURO SA LO NUESTRO MONTERIA | K5: PEAJE NO REGULADO | L5: PEAJES REGIONALES NO REGULADOS OTRO | M5: MAXIMA | N5: SV120 | O5: 507696.9 | P5: 6179.06 | Q5: 46031 | R5: 45992 | S5: 46022 | V5: 2 | W5: BIA ENERGY S.A.S. E.S.P | X5: BIA 49 | Y5: MONTERIA | Z5: INJERMAN GARCIA | AA5: 62371 | AB5: 21139379 | AC5: 1
A6: NO REGULADO | B6: 1333428 | D6: NH | E6: 941510 | F6: 9015884123 | G6: 49 | H6: Frt29125 | I6: 0 | J6: 049 INVERSIONES EURO SA LO NUESTRO MONTERIA | K6: PEAJE NO REGULADO | L6: CONSUMO BASE | M6: NORMAL | N6: SV120 | O6: 0 | P6: 48440.694 | Q6: 46031 | R6: 45992 | S6: 46022 | V6: 2 | W6: BIA ENERGY S.A.S. E.S.P | X6: BIA 49 | Y6: MONTERIA | Z6: INJERMAN GARCIA | AA6: 62371 | AB6: 21139379 | AC6: 1
A7: NO REGULADO | B7: 1341490 | D7: NH | E7: 941513 | F7: 9015884123 | G7: 79 | H7: Frt40029 | I7: 0 | J7: 079 SITES GROUP S.A.S. - HOTEL SITES RECREO | K7: PEAJE NO REGULADO | L7: Aproximacion a decenas Energia | M7: NORMAL | N7: SV120 | O7: -4.33 | P7: 0 | Q7: 46031 | R7: 45992 | S7: 46022 | V7: 2 | W7: BIA ENERGY S.A.S. E.S.P | X7: BIA 79 | Y7: MONTERIA | Z7: INJERMAN GARCIA | AA7: 62371 | AB7: 21135098 | AC7: 0 | AD7: AGPE
A8: NO REGULADO | B8: 1341490 | D8: NH | E8: 941513 | F8: 9015884123 | G8: 79 | H8: Frt40029 | I8: 0 | J8: 079 SITES GROUP S.A.S. - HOTEL SITES RECREO | K8: PEAJE NO REGULADO | L8: PEAJES REGIONALES NO REGULADOS OTRO | M8: MEDIA | N8: SV120 | O8: 3452796.1 | P8: 42023.172 | Q8: 46031 | R8: 45992 | S8: 46022 | V8: 2 | W8: BIA ENERGY S.A.S. E.S.P | X8: BIA 79 | Y8: MONTERIA | Z8: INJERMAN GARCIA | AA8: 62371 | AB8: 21135098 | AC8: 0 | AD8: AGPE
A9: NO REGULADO | B9: 1341490 | D9: NH | E9: 941513 | F9: 9015884123 | G9: 79 | H9: Frt40029 | I9: 0 | J9: 079 SITES GROUP S.A.S. - HOTEL SITES RECREO | K9: PEAJE NO REGULADO | L9: PEAJES REGIONALES NO REGULADOS OTRO | M9: MAXIMA | N9: SV120 | O9: 587808.22 | P9: 7154.076 | Q9: 46031 | R9: 45992 | S9: 46022 | V9: 2 | W9: BIA ENERGY S.A.S. E.S.P | X9: BIA 79 | Y9: MONTERIA | Z9: INJERMAN GARCIA | AA9: 62371 | AB9: 21135098 | AC9: 0 | AD9: AGPE
A10: NO REGULADO | B10: 1333414 | D10: NH | E10: 941507 | F10: 9015884123 | G10: 48 | H10: Frt28526 | I10: 0 | J10: 048 EURO SUPERMERCADO - INVERSIONES EURO SA - MONTERIA | K10: PEAJE NO REGULADO | L10: PEAJES REGIONALES NO REGULADOS OTRO | M10: MEDIA | N10: SV120 | O10: 4290296.7 | P10: 52216.195 | Q10: 46031 | R10: 45992 | S10: 46022 | V10: 2 | W10: BIA ENERGY S.A.S. E.S.P | X10: BIA 48 | Y10: MONTERIA | Z10: INJERMAN GARCIA | AA10: 62371 | AB10: 21107168 | AC10: 1
A11: NO REGULADO | B11: 1395792 | D11: NH | E11: 941515 | F11: 9015884123 | G11: 242 | H11: Frt66036 | I11: 0 | J11: 242 CENTRO PORTAL DE SAN FELIPE CL 30 17-140 OFI 1 PIE DE LA POPA | K11: PEAJE NO REGULADO | L11: Aproximacion a decenas Energia | M11: NORMAL | N11: SV120 | O11: -1.36 | P11: 0 | Q11: 46031 | R11: 45992 | S11: 46022 | V11: 1 | W11: BIA ENERGY S.A.S. E.S.P | X11: BIA 242 | Y11: CARTAGENA | Z11: INJERMAN GARCIA | AA11: 62371 | AB11: 17053469 | AC11: 1
A12: NO REGULADO | B12: 1333428 | D12: NH | E12: 941510 | F12: 9015884123 | G12: 49 | H12: Frt29125 | I12: 0 | J12: 049 INVERSIONES EURO SA LO NUESTRO MONTERIA | K12: PEAJE NO REGULADO | L12: Aproximacion a decenas Energia | M12: NORMAL | N12: SV120 | O12: -1.92 | P12: 0 | Q12: 46031 | R12: 45992 | S12: 46022 | V12: 2 | W12: BIA ENERGY S.A.S. E.S.P | X12: BIA 49 | Y12: MONTERIA | Z12: INJERMAN GARCIA | AA12: 62371 | AB12: 21139379 | AC12: 1
A13: NO REGULADO | B13: 1333428 | D13: NH | E13: 941510 | F13: 9015884123 | G13: 49 | H13: Frt29125 | I13: 0 | J13: 049 INVERSIONES EURO SA LO NUESTRO MONTERIA | K13: PEAJE NO REGULADO | L13: PEN. ENERGIA REACTIVA PEAJES | M13: MAXIMA | N13: SV120 | O13: 49416.47 | P13: 388.256 | Q13: 46031 | R13: 45992 | S13: 46022 | V13: 2 | W13: BIA ENERGY S.A.S. E.S.P | X13: BIA 49 | Y13: MONTERIA | Z13: INJERMAN GARCIA | AA13: 62371 | AB13: 21139379 | AC13: 1
A14: NO REGULADO | B14: 1333414 | D14: NH | E14: 941507 | F14: 9015884123 | G14: 48 | H14: Frt28526 | I14: 0 | J14: 048 EURO SUPERMERCADO - INVERSIONES EURO SA - MONTERIA | K14: PEAJE NO REGULADO | L14: Aproximacion a decenas Energia | M14: NORMAL | N14: SV120 | O14: -1.65 | P14: 0 | Q14: 46031 | R14: 45992 | S14: 46022 | V14: 2 | W14: BIA ENERGY S.A.S. E.S.P | X14: BIA 48 | Y14: MONTERIA | Z14: INJERMAN GARCIA | AA14: 62371 | AB14: 21107168 | AC14: 1
A15: NO REGULADO | B15: 1333414 | D15: NH | E15: 941507 | F15: 9015884123 | G15: 48 | H15: Frt28526 | I15: 0 | J15: 048 EURO SUPERMERCADO - INVERSIONES EURO SA - MONTERIA | K15: PEAJE NO REGULADO | L15: PEN. ENERGIA REACTIVA PEAJES | M15: MAXIMA | N15: SV120 | O15: 8316.35 | P15: 65.34 | Q15: 46031 | R15: 45992 | S15: 46022 | V15: 2 | W15: BIA ENERGY S.A.S. E.S.P | X15: BIA 48 | Y15: MONTERIA | Z15: INJERMAN GARCIA | AA15: 62371 | AB15: 21107168 | AC15: 1
A16: NO REGULADO | B16: 1391980 | D16: NH | E16: 941514 | F16: 9015884123 | G16: 237 | H16: Frt66050 | I16: 0 | J16: 237 MEGAURGENCIAS BLAS DE LEZO TR 54 ISS4 | K16: PEAJE NO REGULADO | L16: PEAJES REGIONALES NO REGULADOS OTRO | M16: MAXIMA | N16: SV120 | O16: 878100.47 | P16: 10687.155 | Q16: 46031 | R16: 45992 | S16: 46022 | V16: 2 | W16: BIA ENERGY S.A.S. E.S.P | X16: BIA 237 | Y16: CARTAGENA | Z16: INJERMAN GARCIA | AA16: 62371 | AB16: 17177216 | AC16: 1
A17: NO REGULADO | B17: 1395792 | D17: NH | E17: 941515 | F17: 9015884123 | G17: 242 | H17: Frt66036 | I17: 0 | J17: 242 CENTRO PORTAL DE SAN FELIPE CL 30 17-140 OFI 1 PIE DE LA POPA | K17: PEAJE NO REGULADO | L17: CONSUMO BASE | M17: NORMAL | N17: SV120 | O17: 0 | P17: 57069.388 | Q17: 46031 | R17: 45992 | S17: 46022 | V17: 1 | W17: BIA ENERGY S.A.S. E.S.P | X17: BIA 242 | Y17: CARTAGENA | Z17: INJERMAN GARCIA | AA17: 62371 | AB17: 17053469 | AC17: 1
A18: NO REGULADO | B18: 1333414 | D18: NH | E18: 941507 | F18: 9015884123 | G18: 48 | H18: Frt28526 | I18: 0 | J18: 048 EURO SUPERMERCADO - INVERSIONES EURO SA - MONTERIA | K18: PEAJE NO REGULADO | L18: PEAJES REGIONALES NO REGULADOS OTRO | M18: MAXIMA | N18: SV120 | O18: 591580.94 | P18: 7199.993 | Q18: 46031 | R18: 45992 | S18: 46022 | V18: 2 | W18: BIA ENERGY S.A.S. E.S.P | X18: BIA 48 | Y18: MONTERIA | Z18: INJERMAN GARCIA | AA18: 62371 | AB18: 21107168 | AC18: 1
A19: NO REGULADO | B19: 1333428 | D19: NH | E19: 941510 | F19: 9015884123 | G19: 49 | H19: Frt29125 | I19: 0 | J19: 049 INVERSIONES EURO SA LO NUESTRO MONTERIA | K19: PEAJE NO REGULADO | L19: PEN. ENERGIA REACTIVA PEAJES | M19: MEDIA | N19: SV120 | O19: 301519.43 | P19: 2368.982 | Q19: 46031 | R19: 45992 | S19: 46022 | V19: 2 | W19: BIA ENERGY S.A.S. E.S.P | X19: BIA 49 | Y19: MONTERIA | Z19: INJERMAN GARCIA | AA19: 62371 | AB19: 21139379 | AC19: 1
A20: NO REGULADO | B20: 1391980 | D20: NH | E20: 941514 | F20: 9015884123 | G20: 237 | H20: Frt66050 | I20: 0 | J20: 237 MEGAURGENCIAS BLAS DE LEZO TR 54 ISS4 | K20: PEAJE NO REGULADO | L20: Aproximacion a decenas Energia | M20: NORMAL | N20: SV120 | O20: 4.69 | P20: 0 | Q20: 46031 | R20: 45992 | S20: 46022 | V20: 2 | W20: BIA ENERGY S.A.S. E.S.P | X20: BIA 237 | Y20: CARTAGENA | Z20: INJERMAN GARCIA | AA20: 62371 | AB20: 17177216 | AC20: 1
A21: NO REGULADO | B21: 1395792 | D21: NH | E21: 941515 | F21: 9015884123 | G21: 242 | H21: Frt66036 | I21: 0 | J21: 242 CENTRO PORTAL DE SAN FELIPE CL 30 17-140 OFI 1 PIE DE LA POPA | K21: PEAJE NO REGULADO | L21: PEAJES REGIONALES NO REGULADOS OTRO | M21: MAXIMA | N21: SV120 | O21: 1011876.9 | P21: 9369.599 | Q21: 46031 | R21: 45992 | S21: 46022 | V21: 1 | W21: BIA ENERGY S.A.S. E.S.P | X21: BIA 242 | Y21: CARTAGENA | Z21: INJERMAN GARCIA | AA21: 62371 | AB21: 17053469 | AC21: 1
... A25: NO REGULADO | B25: 1405491 | D25: NH | E25: 941518 | F25: 9015884123 | G25: 305 | H25: Frt45137 | I25: 0 | J25: 305 PAISAR SAS | K25: PEAJE NO REGULADO | L25: CONSUMO BASE | M25: NORMAL | N25: SV120 | O25: 0 | P25: 69919.045 | Q25: 46031 | R25: 45992 | S25: 46022 | V25: 2 | W25: BIA ENERGY S.A.S. E.S.P | X25: BIA 305 | Y25: CARTAGENA | Z25: INJERMAN GARCIA | AA25: 62371 | AB25: 19397544 | AC25: 1
A26: NO REGULADO | B26: 1341490 | D26: NH | E26: 941513 | F26: 9015884123 | G26: 79 | H26: Frt40029 | I26: 0 | J26: 079 SITES GROUP S.A.S. - HOTEL SITES RECREO | K26: PEAJE NO REGULADO | L26: CONSUMO BASE | M26: NORMAL | N26: SV120 | O26: 0 | P26: 49177.248 | Q26: 46031 | R26: 45992 | S26: 46022 | V26: 2 | W26: BIA ENERGY S.A.S. E.S.P | X26: BIA 79 | Y26: MONTERIA | Z26: INJERMAN GARCIA | AA26: 62371 | AB26: 21135098 | AC26: 0 | AD26: AGPE
A27: NO REGULADO | B27: 1391980 | D27: NH | E27: 941514 | F27: 9015884123 | G27: 237 | H27: Frt66050 | I27: 0 | J27: 237 MEGAURGENCIAS BLAS DE LEZO TR 54 ISS4 | K27: PEAJE NO REGULADO | L27: PEAJES REGIONALES NO REGULADOS OTRO | M27: MEDIA | N27: SV120 | O27: 5779694.8 | P27: 70343.311 | Q27: 46031 | R27: 45992 | S27: 46022 | V27: 2 | W27: BIA ENERGY S.A.S. E.S.P | X27: BIA 237 | Y27: CARTAGENA | Z27: INJERMAN GARCIA | AA27: 62371 | AB27: 17177216 | AC27: 1
A28: NO REGULADO | B28: 1391980 | D28: NH | E28: 941514 | F28: 9015884123 | G28: 237 | H28: Frt66050 | I28: 0 | J28: 237 MEGAURGENCIAS BLAS DE LEZO TR 54 ISS4 | K28: PEAJE NO REGULADO | L28: CONSUMO BASE | M28: NORMAL | N28: SV120 | O28: 0 | P28: 81030.466 | Q28: 46031 | R28: 45992 | S28: 46022 | V28: 2 | W28: BIA ENERGY S.A.S. E.S.P | X28: BIA 237 | Y28: CARTAGENA | Z28: INJERMAN GARCIA | AA28: 62371 | AB28: 17177216 | AC28: 1
A29: NO REGULADO | B29: 1395792 | D29: NH | E29: 941515 | F29: 9015884123 | G29: 242 | H29: Frt66036 | I29: 0 | J29: 242 CENTRO PORTAL DE SAN FELIPE CL 30 17-140 OFI 1 PIE DE LA POPA | K29: PEAJE NO REGULADO | L29: PEAJES REGIONALES NO REGULADOS OTRO | M29: MEDIA | N29: SV120 | O29: 5151374.5 | P29: 47699.789 | Q29: 46031 | R29: 45992 | S29: 46022 | V29: 1 | W29: BIA ENERGY S.A.S. E.S.P | X29: BIA 242 | Y29: CARTAGENA | Z29: INJERMAN GARCIA | AA29: 62371 | AB29: 17053469 | AC29: 1
A30: NO REGULADO | B30: 1405491 | D30: NH | E30: 941518 | F30: 9015884123 | G30: 305 | H30: Frt45137 | I30: 0 | J30: 305 PAISAR SAS | K30: PEAJE NO REGULADO | L30: PEAJES REGIONALES NO REGULADOS OTRO | M30: MAXIMA | N30: SV120 | O30: 705240.02 | P30: 8583.311 | Q30: 46031 | R30: 45992 | S30: 46022 | V30: 2 | W30: BIA ENERGY S.A.S. E.S.P | X30: BIA 305 | Y30: CARTAGENA | Z30: INJERMAN GARCIA | AA30: 62371 | AB30: 19397544 | AC30: 1
A31: REGULADO | B31: 1363519 | D31: NH | E31: 946809 | F31: 9015884123 | G31: 504 | H31: Frt78424 | I31: 0 | J31: 504 MODA ENTERPRISE SAS 2 CL 25 54-20 P 1 LOC 1 | K31: PEAJE NO REGULADO | L31: PEN. ENERGIA REACTIVA PEAJES | M31: NORMAL | N31: SV120 | O31: 385.05 | P31: 2.36 | Q31: 46033 | R31: 45992 | S31: 46022 | V31: 1 | W31: BIA ENERGY S.A.S. E.S.P | X31: BIA 504 | Y31: EL CARMEN DE BOLIVAR | Z31: INJERMAN GARCIA | AA31: 62371 | AB31: 19792503 | AC31: 1
A32: REGULADO | B32: 1415369 | D32: NH | E32: 946474 | F32: 9015884123 | G32: 397 | H32: Frt74848 | I32: 0 | J32: 397 DISTRIBUCIONES PHARMASER LIMITADA CR 2 12A-35 | K32: PEAJE NO REGULADO | L32: Aproximacion a decenas Energia | M32: NORMAL | N32: SV120 | O32: 0.57 | P32: 0 | Q32: 46033 | R32: 45992 | S32: 46022 | V32: 1 | W32: BIA ENERGY S.A.S. E.S.P | X32: BIA 397 | Y32: PUERTO ESCONDIDO | Z32: INJERMAN GARCIA | AA32: 62371 | AB32: 12901850 | AC32: 0
A33: REGULADO | B33: 1360644 | D33: NH | E33: 945897 | F33: 9015884123 | G33: 146 | H33: Frt59463 | I33: 0 | J33: 146 COPSERVIR LTDA TR 3B 15-5 | K33: PEAJE NO REGULADO | L33: PEN. ENERGIA REACTIVA PEAJES | M33: NORMAL | N33: SV120 | O33: 6196.87 | P33: 31.362 | Q33: 46033 | R33: 45992 | S33: 46022 | V33: 1 | W33: BIA ENERGY S.A.S. E.S.P | X33: BIA 146 | Y33: MAGANGUE | Z33: INJERMAN GARCIA | AA33: 62371 | AB33: 17583420 | AC33: 0
A34: REGULADO | B34: 1414342 | D34: NH | E34: 946436 | F34: 9015884123 | G34: 385 | H34: Frt74488 | I34: 0 | J34: 385 DISTRIBUCIONES PHARMASER LIMITADA CL 23 56-70 P 1 APTO 2 | K34: PEAJE NO REGULADO | L34: Aproximacion a decenas Energia | M34: NORMAL | N34: SV120 | O34: 3 | P34: 0 | Q34: 46033 | R34: 45992 | S34: 46022 | V34: 1 | W34: BIA ENERGY S.A.S. E.S.P | X34: BIA 385 | Y34: EL CARMEN DE BOLIVAR | Z34: INJERMAN GARCIA | AA34: 62371 | AB34: 21342685 | AC34: 0
A35: REGULADO | B35: 1414342 | D35: NH | E35: 946436 | F35: 9015884123 | G35: 385 | H35: Frt74488 | I35: 0 | J35: 385 DISTRIBUCIONES PHARMASER LIMITADA CL 23 56-70 P 1 APTO 2 | K35: PEAJE NO REGULADO | L35: PEAJES REGIONALES REGULADOS OTROS | M35: NORMAL | N35: SV120 | O35: 595431.73 | P35: 4180.479 | Q35: 46033 | R35: 45992 | S35: 46022 | V35: 1 | W35: BIA ENERGY S.A.S. E.S.P | X35: BIA 385 | Y35: EL CARMEN DE BOLIVAR | Z35: INJERMAN GARCIA | AA35: 62371 | AB35: 21342685 | AC35: 0
A36: REGULADO | B36: 1415531 | D36: NH | E36: 946530 | F36: 9015884123 | G36: 414 | H36: Frt74031 | I36: 0 | J36: 414 ASOCIADOS GARCIA CASTRO CR 50 25 35 | K36: PEAJE NO REGULADO | L36: Aproximacion a decenas Energia | M36: NORMAL | N36: SV120 | O36: -0.53 | P36: 0 | Q36: 46033 | R36: 45992 | S36: 46022 | V36: 1 | W36: BIA ENERGY S.A.S. E.S.P | X36: BIA 414 | Y36: EL CARMEN DE BOLIVAR | Z36: INJERMAN GARCIA | AA36: 62371 | AB36: 17619157 | AC36: 0
A37: REGULADO | B37: 1415531 | D37: NH | E37: 946530 | F37: 9015884123 | G37: 414 | H37: Frt74031 | I37: 0 | J37: 414 ASOCIADOS GARCIA CASTRO CR 50 25 35 | K37: PEAJE NO REGULADO | L37: CONSUMO BASE | M37: NORMAL | N37: SV120 | O37: 0 | P37: 1946.203 | Q37: 46033 | R37: 45992 | S37: 46022 | V37: 1 | W37: BIA ENERGY S.A.S. E.S.P | X37: BIA 414 | Y37: EL CARMEN DE BOLIVAR | Z37: INJERMAN GARCIA | AA37: 62371 | AB37: 17619157 | AC37: 0
A38: REGULADO | B38: 1377539 | D38: NH | E38: 945961 | F38: 9015884123 | G38: 198 | H38: Frt60938 | I38: 0 | J38: 198 IPS INTEGRAL CLINICAL CARE S.A.S CL 16 9A-131 P1 APTO 1 | K38: PEAJE NO REGULADO | L38: PEAJES REGIONALES REGULADOS OTROS | M38: NORMAL | N38: SV120 | O38: 1607296.4 | P38: 11284.701 | Q38: 46033 | R38: 45992 | S38: 46022 | V38: 1 | W38: BIA ENERGY S.A.S. E.S.P | X38: BIA 198 | Y38: MAGANGUE | Z38: INJERMAN GARCIA | AA38: 62371 | AB38: 17579804 | AC38: 0
... A304: REGULADO | B304: 1354736 | D304: NH | E304: 945356 | F304: 9015884123 | G304: 98 | H304: Frt58820 | I304: 0 | J304: 098 COPSERVIR LTDA CR 1 10-130 P 1 LOC 1 | K304: PEAJE NO REGULADO | L304: Aproximacion a decenas Energia | M304: NORMAL | N304: SV120 | O304: -1.32 | P304: 0 | Q304: 46033 | R304: 45992 | S304: 46022 | V304: 1 | W304: BIA ENERGY S.A.S. E.S.P | X304: BIA 98 | Y304: CARTAGENA | Z304: INJERMAN GARCIA | AA304: 62371 | AB304: 18534189 | AC304: 1
A305: REGULADO | B305: 1345486 | D305: NH | E305: 945282 | F305: 9015884123 | G305: 76 | H305: Frt57786 | I305: 0 | J305: 076 JUANAUTOS EL CERRO SAS CL 29B 18A-209 | K305: PEAJE NO REGULADO | L305: Aproximacion a decenas Energia | M305: NORMAL | N305: SV120 | O305: 0.08 | P305: 0 | Q305: 46033 | R305: 45992 | S305: 46022 | V305: 1 | W305: BIA ENERGY S.A.S. E.S.P | X305: BIA 76 | Y305: CARTAGENA | Z305: INJERMAN GARCIA | AA305: 62371 | AB305: 18508479 | AC305: 1 | AD305: AGPE
A306: REGULADO | B306: 1345488 | D306: NH | E306: 945285 | F306: 9015884123 | G306: 77 | H306: Frt57787 | I306: 0 | J306: 077 RESTAURANTE EUREKA | K306: PEAJE NO REGULADO | L306: PEAJES REGIONALES REGULADOS OTROS | M306: NORMAL | N306: SV120 | O306: 900070.4 | P306: 6319.323 | Q306: 46033 | R306: 45992 | S306: 46022 | V306: 1 | W306: BIA ENERGY S.A.S. E.S.P | X306: BIA 77 | Y306: CARTAGENA | Z306: INJERMAN GARCIA | AA306: 62371 | AB306: 21116819 | AC306: 0
A307: REGULADO | B307: 1354733 | D307: NH | E307: 945334 | F307: 9015884123 | G307: 91 | H307: Frt58783 | I307: 0 | J307: 091 COPSERVIR LTDA AV TERM DE TRANSP 54-70 P 1 LOC 6 SECTOR DONA MANUELA | K307: PEAJE NO REGULADO | L307: Aproximacion a decenas Energia | M307: NORMAL | N307: SV120 | O307: 1.79 | P307: 0 | Q307: 46033 | R307: 45992 | S307: 46022 | V307: 1 | W307: BIA ENERGY S.A.S. E.S.P | X307: BIA 91 | Y307: CARTAGENA | Z307: INJERMAN GARCIA | AA307: 62371 | AB307: 18816558 | AC307: 1
A308: REGULADO | B308: 1354736 | D308: NH | E308: 945356 | F308: 9015884123 | G308: 98 | H308: Frt58820 | I308: 0 | J308: 098 COPSERVIR LTDA CR 1 10-130 P 1 LOC 1 | K308: PEAJE NO REGULADO | L308: CONSUMO BASE | M308: NORMAL | N308: SV120 | O308: 0 | P308: 5201.188 | Q308: 46033 | R308: 45992 | S308: 46022 | V308: 1 | W308: BIA ENERGY S.A.S. E.S.P | X308: BIA 98 | Y308: CARTAGENA | Z308: INJERMAN GARCIA | AA308: 62371 | AB308: 18534189 | AC308: 1
...
