Workbook

Sheet Fuente resumen_peajes SIEC
A1: AÑO | B1: MES | C1: NIT | D1: COMERCIALIZADOR | E1: CODIGO SIC | F1: CTA | G1: CLIENTE | H1: NT | I1: ENERGIA | J1: PERIODO | K1: KW-H | L1: VALOR | M1: VALOR M | N1: MESES ACUMULADOS PENALIZANDO | O1: REACTIVA | P1: TARIFA ACTIVA | Q1: TARIFA REACTIVA
A2: 2025 | B2: 12 | C2: 901588412 | D2: BIA ENERGY SAS ESP | E2: Frt82962 | F2: 1295010112 | G2: PEREZ MONTAÑEZ MIGUEL | H2: 1 | I2: ACTIVA | J2: Monomia OC | K2: 1193 | L2: 296136 | M2: =+VLOOKUP(E2,'[1]VALOR M'!A:C,2,FALSE) -> 1 | N2: =+VLOOKUP(E2,'[1]VALOR M'!A:C,3,FALSE) -> 0 | O2: 0 | P2: 248.22771 | Q2: 289.6581
A3: 2025 | B3: 12 | C3: 901588412 | D3: BIA ENERGY SAS ESP | E3: Frt07988 | F3: 1236415462 | G3: BODEGA INDUSTRIAL COCACOLA | H3: 1 | I3: ACTIVA | J3: Monomia OC | K3: 5570 | L3: 921407 | M3: =+VLOOKUP(E3,'[1]VALOR M'!A:C,2,FALSE) -> 1 | N3: =+VLOOKUP(E3,'[1]VALOR M'!A:C,3,FALSE) -> 0 | O3: 0 | P3: 165.42318 | Q3: 206.85357
A4: 2025 | B4: 12 | C4: 901588412 | D4: BIA ENERGY SAS ESP | E4: Frt82543 | F4: 1295000243 | G4: TORRES DE ALVAREZ LILIA DEL CARMEN | H4: 1 | I4: ACTIVA | J4: Monomia OC | K4: 3555 | L4: 882449 | M4: =+VLOOKUP(E4,'[1]VALOR M'!A:C,2,FALSE) -> 1 | N4: =+VLOOKUP(E4,'[1]VALOR M'!A:C,3,FALSE) -> 0 | O4: 0 | P4: 248.22771 | Q4: 289.6581
A5: 2025 | B5: 12 | C5: 901588412 | D5: BIA ENERGY SAS ESP | E5: Frt78079 | F5: 1291404003 | G5: P A VIVA MALLS | H5: 1 | I5: ACTIVA | J5: Monomia OC | K5: 4659 | L5: 770707 | M5: =+VLOOKUP(E5,'[1]VALOR M'!A:C,2,FALSE) -> 1 | N5: =+VLOOKUP(E5,'[1]VALOR M'!A:C,3,FALSE) -> 5 | O5: =_xlfn.XLOOKUP(E5,Hoja1!E:E,Hoja1!K:K) -> 249 | P5: 165.42318 | Q5: =_xlfn.XLOOKUP(E5,Hoja1!E:E,Hoja1!P:P) -> 206.85357
A6: 2025 | B6: 12 | C6: 901588412 | D6: BIA ENERGY SAS ESP | E6: Frt75767 | F6: 1289123078 | G6: CERINZA CAICEDO EDGAR | H6: 1 | I6: ACTIVA | J6: Monomia OC | K6: 915 | L6: 227128 | M6: =+VLOOKUP(E6,'[1]VALOR M'!A:C,2,FALSE) -> 1 | N6: =+VLOOKUP(E6,'[1]VALOR M'!A:C,3,FALSE) -> 0 | O6: 0 | P6: 248.22771 | Q6: 289.6581
A7: 2025 | B7: 12 | C7: 901588412 | D7: BIA ENERGY SAS ESP | E7: Frt25603 | F7: 1237710707 | G7: AUTOBUSES AGA DE COLOMBIA SAS | H7: 1 | I7: ACTIVA | J7: Monomia OC | K7: 199 | L7: 49397 | M7: =+VLOOKUP(E7,'[1]VALOR M'!A:C,2,FALSE) -> 10 | N7: =+VLOOKUP(E7,'[1]VALOR M'!A:C,3,FALSE) -> 32 | O7: =_xlfn.XLOOKUP(E7,Hoja1!E:E,Hoja1!K:K) -> 3 | P7: 248.22771 | Q7: =_xlfn.XLOOKUP(E7,Hoja1!E:E,Hoja1!P:P) -> 289.6581
A8: 2025 | B8: 12 | C8: 901588412 | D8: BIA ENERGY SAS ESP | E8: Frt03286 | F8: 1256408428 | G8: FOSFATOS DE BOYACA | H8: 2 | I8: ACTIVA | J8: Monomia OC | K8: 26214 | L8: 4004765 | M8: =+VLOOKUP(E8,'[1]VALOR M'!A:C,2,FALSE) -> 12 | N8: =+VLOOKUP(E8,'[1]VALOR M'!A:C,3,FALSE) -> 60 | O8: =_xlfn.XLOOKUP(E8,Hoja1!E:E,Hoja1!K:K) -> 91 | P8: 152.77201 | Q8: =_xlfn.XLOOKUP(E8,Hoja1!E:E,Hoja1!P:P) -> 189.56883
A9: 2025 | B9: 12 | C9: 901588412 | D9: BIA ENERGY SAS ESP | E9: Frt05156 | F9: 1256411828 | G9: GRAPAS Y PUNTILLAS EL CABALLO LTDA | H9: 3 | I9: ACTIVA | J9: Monomia OC | K9: 232870 | L9: 20594254 | M9: =+VLOOKUP(E9,'[1]VALOR M'!A:C,2,FALSE) -> 1 | N9: =+VLOOKUP(E9,'[1]VALOR M'!A:C,3,FALSE) -> 3 | O9: =_xlfn.XLOOKUP(E9,Hoja1!E:E,Hoja1!K:K) -> 11 | P9: 88.43671 | Q9: =_xlfn.XLOOKUP(E9,Hoja1!E:E,Hoja1!P:P) -> 124.95822
A10: 2025 | B10: 12 | C10: 901588412 | D10: BIA ENERGY SAS ESP | E10: Frt43730 | F10: 1237742088 | G10: TRANSPORTADORA DE GAS INTERNACIONAL SA ESP | H10: 1 | I10: ACTIVA | J10: Monomia OC | K10: 10892 | L10: 1801789 | M10: =+VLOOKUP(E10,'[1]VALOR M'!A:C,2,FALSE) -> 1 | N10: =+VLOOKUP(E10,'[1]VALOR M'!A:C,3,FALSE) -> 0 | O10: =_xlfn.XLOOKUP(E10,Hoja1!E:E,Hoja1!K:K) -> 72 | P10: 165.42318 | Q10: =_xlfn.XLOOKUP(E10,Hoja1!E:E,Hoja1!P:P) -> 206.85357
A11: 2025 | B11: 12 | C11: 901588412 | D11: BIA ENERGY SAS ESP | E11: Frt30314 | F11: 1237737014 | G11: DIAZ CORTES RICARDO | H11: 1 | I11: ACTIVA | J11: Monomia OC | K11: 6439 | L11: 1065160 | M11: =+VLOOKUP(E11,'[1]VALOR M'!A:C,2,FALSE) -> 12 | N11: =+VLOOKUP(E11,'[1]VALOR M'!A:C,3,FALSE) -> 60 | O11: =_xlfn.XLOOKUP(E11,Hoja1!E:E,Hoja1!K:K) -> 44 | P11: 165.42318 | Q11: =_xlfn.XLOOKUP(E11,Hoja1!E:E,Hoja1!P:P) -> 206.85357
A12: 2025 | B12: 12 | C12: 901588412 | D12: BIA ENERGY SAS ESP | E12: Frt24814 | F12: 1237708184 | G12: PATIÑO FERNANDEZ HERNAN | H12: 1 | I12: ACTIVA | J12: Monomia OC | K12: 6612 | L12: 1093778 | M12: =+VLOOKUP(E12,'[1]VALOR M'!A:C,2,FALSE) -> 1 | N12: =+VLOOKUP(E12,'[1]VALOR M'!A:C,3,FALSE) -> 0 | O12: =_xlfn.XLOOKUP(E12,Hoja1!E:E,Hoja1!K:K) -> 5 | P12: 165.42318 | Q12: =_xlfn.XLOOKUP(E12,Hoja1!E:E,Hoja1!P:P) -> 206.85357
A13: 2025 | B13: 12 | C13: 901588412 | D13: BIA ENERGY SAS ESP | E13: Frt23996 | F13: 1237700828 | G13: C/COMER INNOVO PLAZA | H13: 1 | I13: ACTIVA | J13: Monomia OC | K13: 15704 | L13: 2597806 | M13: =+VLOOKUP(E13,'[1]VALOR M'!A:C,2,FALSE) -> 12 | N13: =+VLOOKUP(E13,'[1]VALOR M'!A:C,3,FALSE) -> 43 | O13: =_xlfn.XLOOKUP(E13,Hoja1!E:E,Hoja1!K:K) -> 382 | P13: 165.42318 | Q13: =_xlfn.XLOOKUP(E13,Hoja1!E:E,Hoja1!P:P) -> 206.85357
A14: 2025 | B14: 12 | C14: 901588412 | D14: BIA ENERGY SAS ESP | E14: Frt82055 | F14: 1294995423 | G14: SOLANO SANCHEZ MARIA HERMELINDA | H14: 1 | I14: ACTIVA | J14: Monomia OC | K14: 2159 | L14: 535924 | M14: =+VLOOKUP(E14,'[1]VALOR M'!A:C,2,FALSE) -> 1 | N14: =+VLOOKUP(E14,'[1]VALOR M'!A:C,3,FALSE) -> 2 | O14: =_xlfn.XLOOKUP(E14,Hoja1!E:E,Hoja1!K:K) -> 12 | P14: 248.22771 | Q14: =_xlfn.XLOOKUP(E14,Hoja1!E:E,Hoja1!P:P) -> 289.6581
A15: 2025 | B15: 12 | C15: 901588412 | D15: BIA ENERGY SAS ESP | E15: Frt75541 | F15: 1289115663 | G15: RODRIGUEZ MIGUEL A | H15: 1 | I15: ACTIVA | J15: Monomia OC | K15: 4658 | L15: 1156245 | M15: =+VLOOKUP(E15,'[1]VALOR M'!A:C,2,FALSE) -> 1 | N15: =+VLOOKUP(E15,'[1]VALOR M'!A:C,3,FALSE) -> 6 | O15: =_xlfn.XLOOKUP(E15,Hoja1!E:E,Hoja1!K:K) -> 109 | P15: 248.22771 | Q15: =_xlfn.XLOOKUP(E15,Hoja1!E:E,Hoja1!P:P) -> 289.6581
A16: 2025 | B16: 12 | C16: 901588412 | D16: BIA ENERGY SAS ESP | E16: Frt29442 | F16: 1237716499 | G16: PEGAMASTER LTDA | H16: 1 | I16: ACTIVA | J16: Monomia OC | K16: 14989 | L16: 3720685 | M16: =+VLOOKUP(E16,'[1]VALOR M'!A:C,2,FALSE) -> 1 | N16: =+VLOOKUP(E16,'[1]VALOR M'!A:C,3,FALSE) -> 0 | O16: =_xlfn.XLOOKUP(E16,Hoja1!E:E,Hoja1!K:K) -> 194 | P16: 248.22771 | Q16: =_xlfn.XLOOKUP(E16,Hoja1!E:E,Hoja1!P:P) -> 289.6581
A17: 2025 | B17: 12 | C17: 901588412 | D17: BIA ENERGY SAS ESP | E17: Frt46272 | F17: 1237744642 | G17: TRANSPORTADORA DE GAS INTERNACIONAL SA ESP | H17: 1 | I17: ACTIVA | J17: Monomia OC | K17: 8332 | L17: 1378306 | M17: =+VLOOKUP(E17,'[1]VALOR M'!A:C,2,FALSE) -> 1 | N17: =+VLOOKUP(E17,'[1]VALOR M'!A:C,3,FALSE) -> 0 | O17: =_xlfn.XLOOKUP(E17,Hoja1!E:E,Hoja1!K:K) -> 266 | P17: 165.42318 | Q17: =_xlfn.XLOOKUP(E17,Hoja1!E:E,Hoja1!P:P) -> 206.85357
A18: 2025 | B18: 12 | C18: 901588412 | D18: BIA ENERGY SAS ESP | E18: Frt77553 | F18: 1291403226 | G18: PINILLA DE PAEZ MARIA ADELA | H18: 1 | I18: ACTIVA | J18: Monomia OC | K18: 10172 | L18: 2524972 | M18: =+VLOOKUP(E18,'[1]VALOR M'!A:C,2,FALSE) -> 1 | N18: =+VLOOKUP(E18,'[1]VALOR M'!A:C,3,FALSE) -> 5 | O18: =_xlfn.XLOOKUP(E18,Hoja1!E:E,Hoja1!K:K) -> 309 | P18: 248.22771 | Q18: =_xlfn.XLOOKUP(E18,Hoja1!E:E,Hoja1!P:P) -> 289.6581
... A21: 2025 | B21: 12 | C21: 901588412 | D21: BIA ENERGY SAS ESP | E21: Frt19983 | F21: 1237697691 | G21: PAEZ FERNANDO | H21: 1 | I21: ACTIVA | J21: Monomia OC | K21: 4571 | L21: 756149 | M21: =+VLOOKUP(E21,'[1]VALOR M'!A:C,2,FALSE) -> 1 | N21: =+VLOOKUP(E21,'[1]VALOR M'!A:C,3,FALSE) -> 0 | O21: =_xlfn.XLOOKUP(E21,Hoja1!E:E,Hoja1!K:K) -> 9 | P21: 165.42318 | Q21: =_xlfn.XLOOKUP(E21,Hoja1!E:E,Hoja1!P:P) -> 206.85357
A22: 2025 | B22: 12 | C22: 901588412 | D22: BIA ENERGY SAS ESP | E22: Frt75765 | F22: 1289128983 | G22: PACHON P PUBLIO E | H22: 1 | I22: ACTIVA | J22: Monomia OC | K22: 1491 | L22: 370108 | M22: =+VLOOKUP(E22,'[1]VALOR M'!A:C,2,FALSE) -> 1 | N22: =+VLOOKUP(E22,'[1]VALOR M'!A:C,3,FALSE) -> 0 | O22: 0 | P22: 248.22771 | Q22: 289.6581
A23: 2025 | B23: 12 | C23: 901588412 | D23: BIA ENERGY SAS ESP | E23: Frt25602 | F23: 1237709961 | G23: AUTOBUSES AGA DE COLOMBIA SAS | H23: 1 | I23: ACTIVA | J23: Monomia OC | K23: 13441 | L23: 2223453 | M23: =+VLOOKUP(E23,'[1]VALOR M'!A:C,2,FALSE) -> 1 | N23: =+VLOOKUP(E23,'[1]VALOR M'!A:C,3,FALSE) -> 0 | O23: 0 | P23: 165.42318 | Q23: 206.85357
A24: 2025 | B24: 12 | C24: 901588412 | D24: BIA ENERGY SAS ESP | E24: Frt24595 | F24: 1237704056 | G24: DIAZ HURTADO CARLOS ALBERTO | H24: 1 | I24: ACTIVA | J24: Monomia OC | K24: 8143 | L24: 2021318 | M24: =+VLOOKUP(E24,'[1]VALOR M'!A:C,2,FALSE) -> 1 | N24: =+VLOOKUP(E24,'[1]VALOR M'!A:C,3,FALSE) -> 9 | O24: 0 | P24: 248.22771 | Q24: 289.6581
A25: 2025 | B25: 12 | C25: 901588412 | D25: BIA ENERGY SAS ESP | E25: Frt76767 | F25: 1289145380 | G25: CORREA C. CARLOS G. | H25: 1 | I25: ACTIVA | J25: Monomia OC | K25: 7789 | L25: 1288481 | M25: =+VLOOKUP(E25,'[1]VALOR M'!A:C,2,FALSE) -> 1 | N25: =+VLOOKUP(E25,'[1]VALOR M'!A:C,3,FALSE) -> 6 | O25: =_xlfn.XLOOKUP(E25,Hoja1!E:E,Hoja1!K:K) -> 1471 | P25: 165.42318 | Q25: =_xlfn.XLOOKUP(E25,Hoja1!E:E,Hoja1!P:P) -> 206.85357
A26: 2025 | B26: 12 | C26: 901588412 | D26: BIA ENERGY SAS ESP | E26: Frt24481 | F26: 1237776823 | G26: COMPANIA INTEGRAL DE ALIMENTOS LTDA | H26: 1 | I26: ACTIVA | J26: Monomia OC | K26: 4753 | L26: 1179826 | M26: =+VLOOKUP(E26,'[1]VALOR M'!A:C,2,FALSE) -> 6 | N26: =+VLOOKUP(E26,'[1]VALOR M'!A:C,3,FALSE) -> 26 | O26: =_xlfn.XLOOKUP(E26,Hoja1!E:E,Hoja1!K:K) -> 434 | P26: 248.22771 | Q26: =_xlfn.XLOOKUP(E26,Hoja1!E:E,Hoja1!P:P) -> 289.6581
A27: 2025 | B27: 12 | C27: 901588412 | D27: BIA ENERGY SAS ESP | E27: Frt83749 | F27: 1295410370 | G27: C.I. PROYSER S.A. | H27: 3 | I27: ACTIVA | J27: Monomia OC | K27: 9863 | L27: 872251 | M27: =+VLOOKUP(E27,'[1]VALOR M'!A:C,2,FALSE) -> 1 | N27: =+VLOOKUP(E27,'[1]VALOR M'!A:C,3,FALSE) -> 2 | O27: =_xlfn.XLOOKUP(E27,Hoja1!E:E,Hoja1!K:K) -> 2735 | P27: 88.43671 | Q27: =_xlfn.XLOOKUP(E27,Hoja1!E:E,Hoja1!P:P) -> 124.95822
A28: 2025 | B28: 12 | C28: 901588412 | D28: BIA ENERGY SAS ESP | E28: Frt78456 | F28: 1293156459 | G28: HOLCIM COLOMBIA S.A. | H28: 2 | I28: ACTIVA | J28: Monomia OC | K28: 6673 | L28: 1019448 | M28: =+VLOOKUP(E28,'[1]VALOR M'!A:C,2,FALSE) -> 1 | N28: =+VLOOKUP(E28,'[1]VALOR M'!A:C,3,FALSE) -> 4 | O28: =_xlfn.XLOOKUP(E28,Hoja1!E:E,Hoja1!K:K) -> 534 | P28: 152.77201 | Q28: =_xlfn.XLOOKUP(E28,Hoja1!E:E,Hoja1!P:P) -> 189.56883
A29: 2025 | B29: 12 | C29: 901588412 | D29: BIA ENERGY SAS ESP | E29: Frt07943 | F29: 1237694340 | G29: INDUSTRIAS EXPLORER INGENIERIA SAS | H29: 2 | I29: ACTIVA | J29: Monomia OC | K29: 15068 | L29: 2301968 | M29: =+VLOOKUP(E29,'[1]VALOR M'!A:C,2,FALSE) -> 1 | N29: =+VLOOKUP(E29,'[1]VALOR M'!A:C,3,FALSE) -> 0 | O29: =_xlfn.XLOOKUP(E29,Hoja1!E:E,Hoja1!K:K) -> 104 | P29: 152.77201 | Q29: =_xlfn.XLOOKUP(E29,Hoja1!E:E,Hoja1!P:P) -> 189.56883
A30: 2025 | B30: 12 | C30: 901588412 | D30: BIA ENERGY SAS ESP | E30: Frt24604 | F30: 1237707307 | G30: EL POMAR S A | H30: 1 | I30: ACTIVA | J30: Monomia OC | K30: 13674 | L30: 2261997 | M30: =+VLOOKUP(E30,'[1]VALOR M'!A:C,2,FALSE) -> 12 | N30: =+VLOOKUP(E30,'[1]VALOR M'!A:C,3,FALSE) -> 42 | O30: =_xlfn.XLOOKUP(E30,Hoja1!E:E,Hoja1!K:K) -> 195 | P30: 165.42318 | Q30: =_xlfn.XLOOKUP(E30,Hoja1!E:E,Hoja1!P:P) -> 206.85357
A31: 2025 | B31: 12 | C31: 901588412 | D31: BIA ENERGY SAS ESP | E31: Frt77552 | F31: 1291400885 | G31: P A VIVA MALLS | H31: 1 | I31: ACTIVA | J31: Monomia OC | K31: 4634 | L31: 766571 | M31: =+VLOOKUP(E31,'[1]VALOR M'!A:C,2,FALSE) -> 1 | N31: =+VLOOKUP(E31,'[1]VALOR M'!A:C,3,FALSE) -> 5 | O31: =_xlfn.XLOOKUP(E31,Hoja1!E:E,Hoja1!K:K) -> 1210 | P31: 165.42318 | Q31: =_xlfn.XLOOKUP(E31,Hoja1!E:E,Hoja1!P:P) -> 206.85357
A32: 2025 | B32: 12 | C32: 901588412 | D32: BIA ENERGY SAS ESP | E32: Frt63439 | F32: 1272280708 | G32: CENTRO DE CANCEROLOGIA DE BOYACA LTDA | H32: 2 | I32: ACTIVA | J32: Monomia OC | K32: 37080 | L32: 5664786 | M32: =+VLOOKUP(E32,'[1]VALOR M'!A:C,2,FALSE) -> 1 | N32: =+VLOOKUP(E32,'[1]VALOR M'!A:C,3,FALSE) -> 0 | O32: 0 | P32: 152.77201 | Q32: 189.56883
A33: 2025 | B33: 12 | C33: 901588412 | D33: BIA ENERGY SAS ESP | E33: Frt82951 | F33: 1295006935 | G33: PAN ZEROTTI SAS | H33: 1 | I33: ACTIVA | J33: Monomia OC | K33: 2438 | L33: 605179 | M33: =+VLOOKUP(E33,'[1]VALOR M'!A:C,2,FALSE) -> 1 | N33: =+VLOOKUP(E33,'[1]VALOR M'!A:C,3,FALSE) -> 0 | O33: 0 | P33: 248.22771 | Q33: 289.6581
A34: 2025 | B34: 12 | C34: 901588412 | D34: BIA ENERGY SAS ESP | E34: Frt24596 | F34: 1237705733 | G34: JOSE GUSTAVO QUESADA | H34: 1 | I34: ACTIVA | J34: Monomia OC | K34: 5740 | L34: 949529 | M34: =+VLOOKUP(E34,'[1]VALOR M'!A:C,2,FALSE) -> 12 | N34: =+VLOOKUP(E34,'[1]VALOR M'!A:C,3,FALSE) -> 35 | O34: =_xlfn.XLOOKUP(E34,Hoja1!E:E,Hoja1!K:K) -> 767 | P34: 165.42318 | Q34: =_xlfn.XLOOKUP(E34,Hoja1!E:E,Hoja1!P:P) -> 206.85357
A35: 2025 | B35: 12 | C35: 901588412 | D35: BIA ENERGY SAS ESP | E35: Frt46272 | F35: 1237744642 | G35: TRANSPORTADORA DE GAS INTERNACIONAL SA ESP | H35: 1 | I35: REACTIVA | J35: Monomia OC | K35: 266 | L35: 55062 | M35: =+VLOOKUP(E35,'[1]VALOR M'!A:C,2,FALSE) -> 1 | N35: =+VLOOKUP(E35,'[1]VALOR M'!A:C,3,FALSE) -> 0
A36: 2025 | B36: 12 | C36: 901588412 | D36: BIA ENERGY SAS ESP | E36: Frt19983 | F36: 1237697691 | G36: PAEZ FERNANDO | H36: 1 | I36: REACTIVA | J36: Monomia OC | K36: 9 | L36: 1862 | M36: =+VLOOKUP(E36,'[1]VALOR M'!A:C,2,FALSE) -> 1 | N36: =+VLOOKUP(E36,'[1]VALOR M'!A:C,3,FALSE) -> 0
A37: 2025 | B37: 12 | C37: 901588412 | D37: BIA ENERGY SAS ESP | E37: Frt29442 | F37: 1237716499 | G37: PEGAMASTER LTDA | H37: 1 | I37: REACTIVA | J37: Monomia OC | K37: 194 | L37: 56194 | M37: =+VLOOKUP(E37,'[1]VALOR M'!A:C,2,FALSE) -> 1 | N37: =+VLOOKUP(E37,'[1]VALOR M'!A:C,3,FALSE) -> 0
A38: 2025 | B38: 12 | C38: 901588412 | D38: BIA ENERGY SAS ESP | E38: Frt77552 | F38: 1291400885 | G38: P A VIVA MALLS | H38: 1 | I38: REACTIVA | J38: Monomia OC | K38: 1210 | L38: 250293 | M38: =+VLOOKUP(E38,'[1]VALOR M'!A:C,2,FALSE) -> 1 | N38: =+VLOOKUP(E38,'[1]VALOR M'!A:C,3,FALSE) -> 5
A39: 2025 | B39: 12 | C39: 901588412 | D39: BIA ENERGY SAS ESP | E39: Frt76767 | F39: 1289145380 | G39: CORREA C. CARLOS G. | H39: 1 | I39: REACTIVA | J39: Monomia OC | K39: 1471 | L39: 304282 | M39: =+VLOOKUP(E39,'[1]VALOR M'!A:C,2,FALSE) -> 1 | N39: =+VLOOKUP(E39,'[1]VALOR M'!A:C,3,FALSE) -> 6
A40: 2025 | B40: 12 | C40: 901588412 | D40: BIA ENERGY SAS ESP | E40: Frt24600 | F40: 1237706510 | G40: METROGAS SA | H40: 2 | I40: REACTIVA | J40: Monomia OC | K40: 18 | L40: 3412 | M40: =+VLOOKUP(E40,'[1]VALOR M'!A:C,2,FALSE) -> 1 | N40: =+VLOOKUP(E40,'[1]VALOR M'!A:C,3,FALSE) -> 0
A41: 2025 | B41: 12 | C41: 901588412 | D41: BIA ENERGY SAS ESP | E41: Frt30314 | F41: 1237737014 | G41: DIAZ CORTES RICARDO | H41: 1 | I41: REACTIVA | J41: Monomia OC | K41: 528 | L41: 109219 | M41: =+VLOOKUP(E41,'[1]VALOR M'!A:C,2,FALSE) -> 12 | N41: =+VLOOKUP(E41,'[1]VALOR M'!A:C,3,FALSE) -> 60
A42: 2025 | B42: 12 | C42: 901588412 | D42: BIA ENERGY SAS ESP | E42: Frt25603 | F42: 1237710707 | G42: AUTOBUSES AGA DE COLOMBIA SAS | H42: 1 | I42: REACTIVA | J42: Monomia OC | K42: 30 | L42: 8690 | M42: =+VLOOKUP(E42,'[1]VALOR M'!A:C,2,FALSE) -> 10 | N42: =+VLOOKUP(E42,'[1]VALOR M'!A:C,3,FALSE) -> 32
...

Sheet Hoja1
A1: AÑO | B1: MES | C1: NIT | D1: COMERCIALIZADOR | E1: CODIGO SIC | F1: CTA | G1: CLIENTE | H1: NT | I1: ENERGIA | J1: PERIODO | L1: KW-H | M1: VALOR | N1: VALOR M | O1: MESES ACUMULADOS PENALIZANDO | P1: TARIFA
A2: 2025 | B2: 12 | C2: 901588412 | D2: BIA ENERGY SAS ESP | E2: Frt46272 | F2: 1237744642 | G2: TRANSPORTADORA DE GAS INTERNACIONAL SA ESP | H2: 1 | I2: REACTIVA | J2: Monomia OC | K2: =L2/N2 -> 266 | L2: =266/N2 -> 266 | M2: 55062 | N2: 1 | O2: 0 | P2: 206.85357
A3: 2025 | B3: 12 | C3: 901588412 | D3: BIA ENERGY SAS ESP | E3: Frt19983 | F3: 1237697691 | G3: PAEZ FERNANDO | H3: 1 | I3: REACTIVA | J3: Monomia OC | K3: =L3/N3 -> 9 | L3: 9 | M3: 1862 | N3: 1 | O3: 0 | P3: 206.85357
A4: 2025 | B4: 12 | C4: 901588412 | D4: BIA ENERGY SAS ESP | E4: Frt29442 | F4: 1237716499 | G4: PEGAMASTER LTDA | H4: 1 | I4: REACTIVA | J4: Monomia OC | K4: =L4/N4 -> 194 | L4: 194 | M4: 56194 | N4: 1 | O4: 0 | P4: 289.6581
A5: 2025 | B5: 12 | C5: 901588412 | D5: BIA ENERGY SAS ESP | E5: Frt77552 | F5: 1291400885 | G5: P A VIVA MALLS | H5: 1 | I5: REACTIVA | J5: Monomia OC | K5: =L5/N5 -> 1210 | L5: 1210 | M5: 250293 | N5: 1 | O5: 5 | P5: 206.85357
A6: 2025 | B6: 12 | C6: 901588412 | D6: BIA ENERGY SAS ESP | E6: Frt76767 | F6: 1289145380 | G6: CORREA C. CARLOS G. | H6: 1 | I6: REACTIVA | J6: Monomia OC | K6: =L6/N6 -> 1471 | L6: 1471 | M6: 304282 | N6: 1 | O6: 6 | P6: 206.85357
A7: 2025 | B7: 12 | C7: 901588412 | D7: BIA ENERGY SAS ESP | E7: Frt24600 | F7: 1237706510 | G7: METROGAS SA | H7: 2 | I7: REACTIVA | J7: Monomia OC | K7: =L7/N7 -> 18 | L7: 18 | M7: 3412 | N7: 1 | O7: 0 | P7: 189.56883
A8: 2025 | B8: 12 | C8: 901588412 | D8: BIA ENERGY SAS ESP | E8: Frt30314 | F8: 1237737014 | G8: DIAZ CORTES RICARDO | H8: 1 | I8: REACTIVA | J8: Monomia OC | K8: =L8/N8 -> 44 | L8: 528 | M8: 109219 | N8: 12 | O8: 60 | P8: 206.85357
A9: 2025 | B9: 12 | C9: 901588412 | D9: BIA ENERGY SAS ESP | E9: Frt25603 | F9: 1237710707 | G9: AUTOBUSES AGA DE COLOMBIA SAS | H9: 1 | I9: REACTIVA | J9: Monomia OC | K9: =L9/N9 -> 3 | L9: 30 | M9: 8690 | N9: 10 | O9: 32 | P9: 289.6581
A10: 2025 | B10: 12 | C10: 901588412 | D10: BIA ENERGY SAS ESP | E10: Frt05156 | F10: 1256411828 | G10: GRAPAS Y PUNTILLAS EL CABALLO LTDA | H10: 3 | I10: REACTIVA | J10: Monomia OC | K10: =L10/N10 -> 11 | L10: 11 | M10: 1375 | N10: 1 | O10: 3 | P10: 124.95822
A11: 2025 | B11: 12 | C11: 901588412 | D11: BIA ENERGY SAS ESP | E11: Frt24596 | F11: 1237705733 | G11: JOSE GUSTAVO QUESADA | H11: 1 | I11: REACTIVA | J11: Monomia OC | K11: =L11/N11 -> 767 | L11: 9204 | M11: 1903881 | N11: 12 | O11: 35 | P11: 206.85357
A12: 2025 | B12: 12 | C12: 901588412 | D12: BIA ENERGY SAS ESP | E12: Frt82055 | F12: 1294995423 | G12: SOLANO SANCHEZ MARIA HERMELINDA | H12: 1 | I12: REACTIVA | J12: Monomia OC | K12: =L12/N12 -> 12 | L12: 12 | M12: 3476 | N12: 1 | O12: 2 | P12: 289.6581
A13: 2025 | B13: 12 | C13: 901588412 | D13: BIA ENERGY SAS ESP | E13: Frt24604 | F13: 1237707307 | G13: EL POMAR S A | H13: 1 | I13: REACTIVA | J13: Monomia OC | K13: =L13/N13 -> 195 | L13: 2340 | M13: 484037 | N13: 12 | O13: 42 | P13: 206.85357
A14: 2025 | B14: 12 | C14: 901588412 | D14: BIA ENERGY SAS ESP | E14: Frt78079 | F14: 1291404003 | G14: P A VIVA MALLS | H14: 1 | I14: REACTIVA | J14: Monomia OC | K14: =L14/N14 -> 249 | L14: 249 | M14: 51507 | N14: 1 | O14: 5 | P14: 206.85357
... A26: 2025 | B26: 12 | C26: 901588412 | D26: BIA ENERGY SAS ESP | E26: Frt83749 | F26: 1295410370 | G26: C.I. PROYSER S.A. | H26: 3 | I26: REACTIVA | J26: Reactiva Capacit | K26: =L26/N26 -> 2735 | L26: 2735 | M26: 341761 | N26: 1 | O26: 2 | P26: 124.95822
